<robot
  name="newnursing">

  <link name="world"/>
  <joint
        name="base_connected2_world"
        type="fixed">
        <origin
        xyz="0 0 0.7"
        rpy="0 0 -1.570796" />
        <parent
        link="world" />
        <child
        link="base_Link" />
  </joint>

  <link
    name="base_Link">
    <inertial>
      <origin
        xyz="0.00125118023217667 0.00571211217189015 -0.140709209620161"
        rpy="0 0 0" />
      <mass
        value="95.5038362880811" />
      <inertia
        ixx="11.0907233740476"
        ixy="0.000682554632591413"
        ixz="-0.0517799038169192"
        iyy="11.3066493157079"
        iyz="0.493087614689815"
        izz="1.35548319771507" />
    </inertial>
    <visual>
      <origin
        xyz="0 0 0"
        rpy="0 0 0" />
      <geometry>
        <mesh
          filename="package://assembly/meshes/L0.STL" />
      </geometry>
      <material
        name="">
        <color
          rgba="0.752941176470588 0.752941176470588 0.752941176470588 1" />
      </material>
    </visual>
    <collision>
      <origin
        xyz="0 0 0"
        rpy="0 0 0" />
      <geometry>
        <mesh
          filename="package://assembly/meshes/L0.STL" />
      </geometry>
    </collision>
  </link>

  <joint name="neck_link_joint" type="fixed">
    <origin xyz="0 0 1.052" rpy="0 0 0"/>
    <parent link="base_Link"/>
    <child link="neck_link"/>
  </joint>
  <link name="neck_link"/>
  
  <joint name="camera_joint" type="fixed">
    <origin xyz="0.0781 0 -0.322" rpy="0 -0.000528726 0"/>
    <parent link="neck_link"/>
    <child link="camera_mount_link"/>
  </joint>
  <link name="camera_mount_link"/>


  <link
    name="LR1">
    <inertial>
      <origin
        xyz="8.98828320106126E-09 -0.00293592242745783 -0.0212534141841283"
        rpy="0 0 0" />
      <mass
        value="2.15747169774314" />
      <inertia
        ixx="0.0039159844519028"
        ixy="9.55754457347691E-10"
        ixz="-2.77111575117903E-10"
        iyy="0.00365262349092814"
        iyz="0.000102299773397755"
        izz="0.00239174812495883" />
    </inertial>
    <visual>
      <origin
        xyz="0 0 0"
        rpy="0 0 0" />
      <geometry>
        <mesh
          filename="package://assembly/meshes/LR1.STL" />
      </geometry>
      <material
        name="">
        <color
          rgba="0.866666666666667 0.866666666666667 0.890196078431372 1" />
      </material>
    </visual>
    <collision>
      <origin
        xyz="0 0 0"
        rpy="0 0 0" />
      <geometry>
        <mesh
          filename="package://assembly/meshes/LR1.STL" />
      </geometry>
    </collision>
  </link>
  <joint
    name="JR1"
    type="revolute">
    <origin
      xyz="0.21718 0.005 0.33244"
      rpy="1.5708 -1.2217 3.1416" />
    <parent
      link="base_Link" />
    <child
      link="LR1" />
    <axis
      xyz="0 -1 0" />
    <limit
      lower="-2.0858"
      upper="0.6184"
      effort="120"
      velocity="6" />
    <dynamics
      damping="2"
      friction="0.3" />
  </joint>



  <link
    name="LR2">
    <inertial>
      <origin
        xyz="7.96974763961344E-10 0.0015000865054824 -0.0924071969744042"
        rpy="0 0 0" />
      <mass
        value="1.37522903314702" />
      <inertia
        ixx="0.00255574962153346"
        ixy="-8.72623878301597E-11"
        ixz="2.40396158064827E-10"
        iyy="0.00236365743499222"
        iyz="-0.000425917906294408"
        izz="0.00129320260941946" />
    </inertial>
    <visual>
      <origin
        xyz="0 0 0"
        rpy="0 0 0" />
      <geometry>
        <mesh
          filename="package://assembly/meshes/LR2.STL" />
      </geometry>
      <material
        name="">
        <color
          rgba="0.866666666666667 0.866666666666667 0.890196078431372 1" />
      </material>
    </visual>
    <collision>
      <origin
        xyz="0 0 0"
        rpy="0 0 0" />
      <geometry>
        <mesh
          filename="package://assembly/meshes/LR2.STL" />
      </geometry>
    </collision>
  </link>
  <joint
    name="JR2"
    type="revolute">
    <origin
      xyz="0 0 0"
      rpy="1.5708 1.6259E-14 1.7757" />
    <parent
      link="LR1" />
    <child
      link="LR2" />
    <axis
      xyz="0 -1 0" />
    <limit
      lower="-0.0199"
      upper="1.9192"
      effort="120"
      velocity="6" />
    <dynamics
      damping="2"
      friction="0.3" />
  </joint>


  <link
    name="LR3">
    <inertial>
      <origin
        xyz="4.65691851040707E-08 -0.0512426233861256 0.016370508405232"
        rpy="0 0 0" />
      <mass
        value="1.34826710835918" />
      <inertia
        ixx="0.00208076254874643"
        ixy="-4.03797785551324E-09"
        ixz="-4.6534220074945E-10"
        iyy="0.00184109939176927"
        iyz="0.000106562785244077"
        izz="0.00102109494898677" />
    </inertial>
    <visual>
      <origin
        xyz="0 0 0"
        rpy="0 0 0" />
      <geometry>
        <mesh
          filename="package://assembly/meshes/LR3.STL" />
      </geometry>
      <material
        name="">
        <color
          rgba="0.866666666666667 0.866666666666667 0.890196078431372 1" />
      </material>
    </visual>
    <collision>
      <origin
        xyz="0 0 0"
        rpy="0 0 0" />
      <geometry>
        <mesh
          filename="package://assembly/meshes/LR3.STL" />
      </geometry>
    </collision>
  </link>
  <joint
    name="JR3"
    type="revolute">
    <origin
      xyz="0 -0.005 -0.15692"
      rpy="1.5708 -3.3497E-15 -1.5747" />
    <parent
      link="LR2" />
    <child
      link="LR3" />
    <axis
      xyz="0 1 0" />
    <limit
      lower="-0.8610"
      upper="1.6427"
      effort="60"
      velocity="6" />
    <dynamics
      damping="2"
      friction="0.3" />
  </joint>


  <link
    name="LR4">
    <inertial>
      <origin
        xyz="-2.50365132705571E-10 0.00287135059851118 -0.0862731965495294"
        rpy="0 0 0" />
      <mass
        value="1.24992119764275" />
      <inertia
        ixx="0.00182610105204982"
        ixy="7.77646565831212E-12"
        ixz="-2.99027605994251E-13"
        iyy="0.00172088352354759"
        iyz="-0.000159721713914947"
        izz="0.000943726351810488" />
    </inertial>
    <visual>
      <origin
        xyz="0 0 0"
        rpy="0 0 0" />
      <geometry>
        <mesh
          filename="package://assembly/meshes/LR4.STL" />
      </geometry>
      <material
        name="">
        <color
          rgba="0.866666666666667 0.866666666666667 0.890196078431372 1" />
      </material>
    </visual>
    <collision>
      <origin
        xyz="0 0 0"
        rpy="0 0 0" />
      <geometry>
        <mesh
          filename="package://assembly/meshes/LR4.STL" />
      </geometry>
    </collision>
  </link>
  <joint
    name="JR4"
    type="revolute">
    <origin
      xyz="0 -0.056081 0"
      rpy="-1.5708 6.415E-15 -0.0064215" />
    <parent
      link="LR3" />
    <child
      link="LR4" />
    <axis
      xyz="0 -1 0" />
    <limit
      lower="-1.6955"
      upper="0.0004"
      effort="60"
      velocity="6" />
    <dynamics
      damping="2"
      friction="0.3" />
  </joint>


  <link
    name="LR5">
    <inertial>
      <origin
        xyz="-4.09562333173667E-07 -0.0455211167168911 -0.0126817877422067"
        rpy="0 0 0" />
      <mass
        value="0.693177401802725" />
      <inertia
        ixx="0.000866324066214255"
        ixy="-3.95415599163896E-09"
        ixz="-2.49468249606226E-09"
        iyy="0.000576262199993781"
        iyz="0.000175455226079061"
        izz="0.00064519904021367" />
    </inertial>
    <visual>
      <origin
        xyz="0 0 0"
        rpy="0 0 0" />
      <geometry>
        <mesh
          filename="package://assembly/meshes/LR5.STL" />
      </geometry>
      <material
        name="">
        <color
          rgba="0.866666666666667 0.866666666666667 0.890196078431372 1" />
      </material>
    </visual>
    <collision>
      <origin
        xyz="0 0 0"
        rpy="0 0 0" />
      <geometry>
        <mesh
          filename="package://assembly/meshes/LR5.STL" />
      </geometry>
    </collision>
  </link>
  <joint
    name="JR5"
    type="revolute">
    <origin
      xyz="0 0 -0.1476"
      rpy="1.5708 1.1861E-14 0.0046909" />
    <parent
      link="LR4" />
    <child
      link="LR5" />
    <axis
      xyz="0 1 0" />
    <limit
      lower="-1.6711"
      upper="1.6270"
      effort="60"
      velocity="6" />
    <dynamics
      damping="2"
      friction="0.3" />
  </joint>

  <link
    name="LR6">
    <inertial>
      <origin
        xyz="-0.00327778131852274 -0.114201821910276 0.00943175908361554"
        rpy="0 0 0" />
      <mass
        value="0.173615825258922" />
      <inertia
        ixx="0.000964616909090983"
        ixy="-1.91278655045261E-05"
        ixz="1.73215247124374E-05"
        iyy="0.000130345754178878"
        iyz="-5.80900699845923E-05"
        izz="0.000955542750560925" />
    </inertial>
    <visual>
      <origin
        xyz="0 0 0"
        rpy="0 0 0" />
      <geometry>
        <mesh
          filename="package://assembly/meshes/LR6.STL" />
      </geometry>
      <material
        name="">
        <color
          rgba="0.866666666666667 0.866666666666667 0.890196078431372 1" />
      </material>
    </visual>
    <collision>
      <origin
        xyz="0 0 0"
        rpy="0 0 0" />
      <geometry>
        <mesh
          filename="package://assembly/meshes/LR6.STL" />
      </geometry>
    </collision>
  </link>
  <joint
    name="JR6"
    type="revolute">
    <origin
      xyz="0 -0.063404 0"
      rpy="8.5792E-16 5.3161E-15 -0.0042912" />
    <parent
      link="LR5" />
    <child
      link="LR6" />
    <axis
      xyz="0 0 1" />
    <limit
      lower="-0.6010"
      upper="0.4415"
      effort="30"
      velocity="6" />
    <dynamics
      damping="2"
      friction="0.3" />
  </joint>


  <link name="Rplam_Link"/>
  <joint
    name="Rplam_joint"
    type="fixed">
    <origin
      xyz="0 -0.16 0"
      rpy="-4.7783E-19 -1.5708 -9.2245E-20" />
    <parent
      link="LR6" />
    <child
      link="Rplam_Link" />
  </joint>




  <link
    name="LL1">
    <inertial>
      <origin
        xyz="-6.37042760209816E-09 -0.00311606961400701 -0.0203021739937478"
        rpy="0 0 0" />
      <mass
        value="0.742414555702471" />
      <inertia
        ixx="0.0012740812827287"
        ixy="-8.44845865087453E-11"
        ixz="-1.69158880334627E-10"
        iyy="0.00117846286241893"
        iyz="3.56009846333508E-05"
        izz="0.000802045043418103" />
    </inertial>
    <visual>
      <origin
        xyz="0 0 0"
        rpy="0 0 0" />
      <geometry>
        <mesh
          filename="package://assembly/meshes/LL1.STL" />
      </geometry>
      <material
        name="">
        <color
          rgba="0.752941176470588 0.752941176470588 0.752941176470588 1" />
      </material>
    </visual>
    <collision>
      <origin
        xyz="0 0 0"
        rpy="0 0 0" />
      <geometry>
        <mesh
          filename="package://assembly/meshes/LL1.STL" />
      </geometry>
    </collision>
  </link>
  <joint
    name="JL1"
    type="revolute">
    <origin
      xyz="-0.21718 0.005 0.33244"
      rpy="1.5708 1.2217 -3.1416" />
    <parent
      link="base_Link" />
    <child
      link="LL1" />
    <axis
      xyz="0 -1 0" />
    <limit
      lower="-0.4998"
      upper="2.5405"
      effort="120"
      velocity="6" />
  </joint>


  <link
    name="LL2">
    <inertial>
      <origin
        xyz="-1.59942401600777E-07 -0.0900949903759909 -0.00978996979277103"
        rpy="0 0 0" />
      <mass
        value="0.68682778469314" />
      <inertia
        ixx="0.00167905640514389"
        ixy="3.78112905492115E-09"
        ixz="-1.78536754351579E-09"
        iyy="0.000842469561542776"
        iyz="0.000406436027091152"
        izz="0.00154239526729338" />
    </inertial>
    <visual>
      <origin
        xyz="0 0 0"
        rpy="0 0 0" />
      <geometry>
        <mesh
          filename="package://assembly/meshes/LL2.STL" />
      </geometry>
      <material
        name="">
        <color
          rgba="1 0.501960784313725 1 1" />
      </material>
    </visual>
    <collision>
      <origin
        xyz="0 0 0"
        rpy="0 0 0" />
      <geometry>
        <mesh
          filename="package://assembly/meshes/LL2.STL" />
      </geometry>
    </collision>
  </link>
  <joint
    name="JL2"
    type="revolute">
    <origin
      xyz="0 0 0"
      rpy="3.1416 -7.9803E-16 -1.8108" />
    <parent
      link="LL1" />
    <child
      link="LL2" />
    <axis
      xyz="0 0 1" />
    <limit
      lower="-2.2806"
      upper="0.1269"
      effort="120"
      velocity="6" />
  </joint>


  <link
    name="LL3">
    <inertial>
      <origin
        xyz="3.21767517434115E-08 -0.0675560201834257 0.0139465479319382"
        rpy="0 0 0" />
      <mass
        value="0.437839302029068" />
      <inertia
        ixx="0.00058672166818976"
        ixy="-9.21102167300725E-10"
        ixz="-5.62144252678658E-11"
        iyy="0.000545687428782642"
        iyz="1.61583368753071E-05"
        izz="0.00031046233442883" />
    </inertial>
    <visual>
      <origin
        xyz="0 0 0"
        rpy="0 0 0" />
      <geometry>
        <mesh
          filename="package://assembly/meshes/LL3.STL" />
      </geometry>
      <material
        name="">
        <color
          rgba="0.752941176470588 0.752941176470588 0.752941176470588 1" />
      </material>
    </visual>
    <collision>
      <origin
        xyz="0 0 0"
        rpy="0 0 0" />
      <geometry>
        <mesh
          filename="package://assembly/meshes/LL3.STL" />
      </geometry>
    </collision>
  </link>
  <joint
    name="JL3"
    type="revolute">
    <origin
      xyz="0 -0.15287 0.005"
      rpy="5.8768E-13 1.5684 5.8279E-13" />
    <parent
      link="LL2" />
    <child
      link="LL3" />
    <axis
      xyz="0 1 0" />
    <limit
      lower="-1.1300"
      upper="1.4936"
      effort="60"
      velocity="6" />
  </joint>


  <link
    name="LL4">
    <inertial>
      <origin
        xyz="-2.55573985041575E-08 -0.00697068364470027 -0.0912337876171683"
        rpy="0 0 0" />
      <mass
        value="0.564926626991847" />
      <inertia
        ixx="0.00104600587867379"
        ixy="-5.19706723763342E-10"
        ixz="3.39358092068315E-10"
        iyy="0.00094490837319263"
        iyz="0.000173685315173717"
        izz="0.00052296228447961" />
    </inertial>
    <visual>
      <origin
        xyz="0 0 0"
        rpy="0 0 0" />
      <geometry>
        <mesh
          filename="package://assembly/meshes/LL4.STL" />
      </geometry>
      <material
        name="">
        <color
          rgba="1 0.501960784313725 1 1" />
      </material>
    </visual>
    <collision>
      <origin
        xyz="0 0 0"
        rpy="0 0 0" />
      <geometry>
        <mesh
          filename="package://assembly/meshes/LL4.STL" />
      </geometry>
    </collision>
  </link>
  <joint
    name="JL4"
    type="revolute">
    <origin
      xyz="0 -0.070131 0"
      rpy="1.5708 1.5909E-14 -3.1308" />
    <parent
      link="LL3" />
    <child
      link="LL4" />
    <axis
      xyz="0 1 0" />
    <limit
      lower="-0.0017"
      upper="1.7891"
      effort="60"
      velocity="6" />
  </joint>


  <link
    name="LL5">
    <inertial>
      <origin
        xyz="-2.7285871747723E-05 -0.0769462900817405 -0.00393937125918359"
        rpy="0 0 0" />
      <mass
        value="0.307795414476204" />
      <inertia
        ixx="0.00030350174251315"
        ixy="3.65474241742097E-07"
        ixz="4.4686800853968E-08"
        iyy="0.000210127575480133"
        iyz="-9.9553262377435E-06"
        izz="0.000294140122670997" />
    </inertial>
    <visual>
      <origin
        xyz="0 0 0"
        rpy="0 0 0" />
      <geometry>
        <mesh
          filename="package://assembly/meshes/LL5.STL" />
      </geometry>
      <material
        name="">
        <color
          rgba="0.752941176470588 0.752941176470588 0.752941176470588 1" />
      </material>
    </visual>
    <collision>
      <origin
        xyz="0 0 0"
        rpy="0 0 0" />
      <geometry>
        <mesh
          filename="package://assembly/meshes/LL5.STL" />
      </geometry>
    </collision>
  </link>
  <joint
    name="JL5"
    type="revolute">
    <origin
      xyz="0 0 -0.14672"
      rpy="1.5708 3.629E-15 3.1403" />
    <parent
      link="LL4" />
    <child
      link="LL5" />
    <axis
      xyz="0 1 0" />
    <limit
      lower="-0.9529"
      upper="1.1191"
      effort="60"
      velocity="6" />
  </joint>


  <link
    name="LL6">
    <inertial>
      <origin
        xyz="0.0032377127173702 -0.114191079305633 0.00943041174763107"
        rpy="0 0 0" />
      <mass
        value="0.173577655802291" />
      <inertia
        ixx="0.000964471788242522"
        ixy="1.95939539811118E-05"
        ixz="-1.73706278601833E-05"
        iyy="0.000130370358877101"
        iyz="-5.80992206345396E-05"
        izz="0.000955450552032434" />
    </inertial>
    <visual>
      <origin
        xyz="0 0 0"
        rpy="0 0 0" />
      <geometry>
        <mesh
          filename="package://assembly/meshes/LL6.STL" />
      </geometry>
      <material
        name="">
        <color
          rgba="0.866666666666667 0.866666666666667 0.890196078431372 1" />
      </material>
    </visual>
    <collision>
      <origin
        xyz="0 0 0"
        rpy="0 0 0" />
      <geometry>
        <mesh
          filename="package://assembly/meshes/LL6.STL" />
      </geometry>
    </collision>
  </link>
  <joint
    name="JL6"
    type="revolute">
    <origin
      xyz="0 -0.084276 0"
      rpy="1.5384E-15 4.1538E-15 -0.0063056" />
    <parent
      link="LL5" />
    <child
      link="LL6" />
    <axis
      xyz="0 0 1" />
    <limit
      lower="-0.4722"
      upper="0.8769"
      effort="30"
      velocity="6" />
  </joint>

  <link name="Lplam_Link"/>
  <joint
    name="Lplam_joint"
    type="fixed">
    <origin
      xyz="0 -0.16 0"
      rpy="0 -1.5708 0" />
    <parent
      link="LL6" />
    <child
      link="Lplam_Link" />
  </joint>


</robot>
